Workbook

Sheet Cover
B2: Waypoint REIT
B6: ASX: WPR | Bottom-Up 3-Statement, Scenario, Valuation & Returns | FY24A-FY30E
B11: Segment | D11: Service stations & fuel/convenience (net lease, INTERNALLY MANAGED)
B12: Structure | D12: Stapled (Waypoint REIT Ltd / Waypoint REIT Trust)
B13: Manager | D13: Internally managed (VER Limited as RE)
B14: Securities on issue | D14: ~663.0m
B15: NTA (latest disclosed) | D15: $2.90 / security
B16: WACR (latest) | D16: 5.66%
B17: Occupancy / WALE | D17: 100% / 8.4 years
B18: Hedged (latest) | D18: 90% of drawn debt
B19: FY26 DPS | D19: 17.1 cps
B20: Financial year end | D20: 31 December
B21: Model date | D21: June 2026 | 360 Capital internal analysis
B23: DISCLAIMER - Built solely from publicly available information (ASX / results presentations / investor updates / market data). Not produced or endorsed by the manager. Asset-level figures and several balance-sheet lines are ESTIMATED / CALIBRATED to reconcile to disclosed NTA, gearing and WACR - flagged yellow. Replace with Annual Report / 4D before relying on outputs. Internal use only. Not advice.

Sheet Summary
B2: Summary Dashboard - ASX:WPR
C5: FY24A | D5: FY25A | E5: FY26E | F5: FY27E | G5: FY28E | H5: FY29E | I5: FY30E
B6: FFO ($m) | C6: ='P&L'!C12 -> 109.1 | D6: ='P&L'!D12 -> 110.4 | E6: ='P&L'!E12 -> 114.37698 | F6: ='P&L'!F12 -> 116.24978 | G6: ='P&L'!G12 -> 119.58533 | H6: ='P&L'!H12 -> 123.31589 | I6: ='P&L'!I12 -> 126.95858
B7: AFFO ($m) | C7: ='P&L'!C18 -> 107.6 | D7: ='P&L'!D18 -> 108.9 | E7: ='P&L'!E18 -> 112.87698 | F7: ='P&L'!F18 -> 114.74978 | G7: ='P&L'!G18 -> 118.08533 | H7: ='P&L'!H18 -> 121.81589 | I7: ='P&L'!I18 -> 125.45858
B8: FFO / security (cps) | C8: ='P&L'!C20 -> 16.455505 | D8: ='P&L'!D20 -> 16.651584 | E8: ='P&L'!E20 -> 17.335098 | F8: ='P&L'!F20 -> 17.618943 | G8: ='P&L'!G20 -> 18.124481 | H8: ='P&L'!H20 -> 18.68989 | I8: ='P&L'!I20 -> 19.241979
B9: DPS (cps) | C9: ='P&L'!C24 -> 16.48 | D9: ='P&L'!D24 -> 16.64 | E9: ='P&L'!E24 -> 17.335098 | F9: ='P&L'!F24 -> 17.618943 | G9: ='P&L'!G24 -> 18.124481 | H9: ='P&L'!H24 -> 18.68989 | I9: ='P&L'!I24 -> 19.241979
B10: FFO payout (%) | C10: ='P&L'!C25 -> 1.0014885 | D10: ='P&L'!D25 -> 0.99930435 | E10: ='P&L'!E25 -> 1 | F10: ='P&L'!F25 -> 1 | G10: ='P&L'!G25 -> 1 | H10: ='P&L'!H25 -> 1 | I10: ='P&L'!I25 -> 1
B11: AFFO cover (x) | C11: ='Earnings Quality'!C16 -> 0.98478525 | D11: ='Earnings Quality'!D16 -> 0.98709972 | E11: ='Earnings Quality'!E16 -> 0.98688547 | F11: ='Earnings Quality'!F16 -> 0.98709675 | G11: ='Earnings Quality'!G16 -> 0.98745666 | H11: ='Earnings Quality'!H16 -> 0.98783612 | I11: ='Earnings Quality'!I16 -> 0.98818512
B12: Portfolio value ($m) | C12: =Assumptions!C42 -> 2730 | D12: =Assumptions!D42 -> 2858 | E12: =Assumptions!E42 -> 2935.5546 | F12: =Assumptions!F42 -> 3000.5109 | G12: =Assumptions!G42 -> 3083.109 | H12: =Assumptions!H42 -> 3166.0754 | I12: =Assumptions!I42 -> 3249.3179
B13: Net debt ($m) | C13: =Debt!C12 -> 900 | D13: =Debt!D12 -> 935 | E13: =Debt!E12 -> 949.5 | F13: =Debt!F12 -> 956 | G13: =Debt!G12 -> 962.5 | H13: =Debt!H12 -> 969 | I13: =Debt!I12 -> 975.5
B14: Gearing (%) | C14: =Debt!C27 -> 0.31 | D14: =Debt!D27 -> 0.327 | E14: =Debt!E27 -> 0.32311803 | F14: =Debt!F27 -> 0.31829417 | G14: =Debt!G27 -> 0.3118814 | H14: =Debt!H27 -> 0.30576741 | I14: =Debt!I27 -> 0.29993993
B15: ICR (x) | C15: =Debt!C30 -> 3.7275 | D15: =Debt!D30 -> 3.5090909 | E15: =Debt!E30 -> 3.6932033 | F15: =Debt!F30 -> 3.6373892 | G15: =Debt!G30 -> 3.6474906 | H15: =Debt!H30 -> 3.6874551 | I15: =Debt!I30 -> 3.718316
B16: NTA / security ($) | C16: ='Balance Sheet'!C33 -> 2.760181 | D16: ='Balance Sheet'!D33 -> 2.9004525 | E16: ='Balance Sheet'!E33 -> 3.0070546 | F16: ='Balance Sheet'!F33 -> 3.0956516 | G16: ='Balance Sheet'!G33 -> 3.2109866 | H16: ='Balance Sheet'!H33 -> 3.32688 | I16: ='Balance Sheet'!I33 -> 3.4431917
B17: EQ score (0-100) | C17: ='Earnings Quality'!C28 -> 50 | D17: ='Earnings Quality'!D28 -> 58 | E17: ='Earnings Quality'!E28 -> 72 | F17: ='Earnings Quality'!F28 -> 72 | G17: ='Earnings Quality'!G28 -> 72 | H17: ='Earnings Quality'!H28 -> 72 | I17: ='Earnings Quality'!I28 -> 72
B19: Chart data
B20: FFO ($m) | C20: ='P&L'!C12 -> 109.1 | D20: ='P&L'!D12 -> 110.4 | E20: ='P&L'!E12 -> 114.37698 | F20: ='P&L'!F12 -> 116.24978 | G20: ='P&L'!G12 -> 119.58533 | H20: ='P&L'!H12 -> 123.31589 | I20: ='P&L'!I12 -> 126.95858
B21: Distributions ($m) | C21: ='P&L'!C27 -> 109.2624 | D21: ='P&L'!D27 -> 110.3232 | E21: ='P&L'!E27 -> 114.37698 | F21: ='P&L'!F27 -> 116.24978 | G21: ='P&L'!G27 -> 119.58533 | H21: ='P&L'!H27 -> 123.31589 | I21: ='P&L'!I27 -> 126.95858
B22: AFFO cover (x) | C22: ='Earnings Quality'!C16 -> 0.98478525 | D22: ='Earnings Quality'!D16 -> 0.98709972 | E22: ='Earnings Quality'!E16 -> 0.98688547 | F22: ='Earnings Quality'!F16 -> 0.98709675 | G22: ='Earnings Quality'!G16 -> 0.98745666 | H22: ='Earnings Quality'!H16 -> 0.98783612 | I22: ='Earnings Quality'!I16 -> 0.98818512
B23: NTA / sec ($) | C23: ='Balance Sheet'!C33 -> 2.760181 | D23: ='Balance Sheet'!D33 -> 2.9004525 | E23: ='Balance Sheet'!E33 -> 3.0070546 | F23: ='Balance Sheet'!F33 -> 3.0956516 | G23: ='Balance Sheet'!G33 -> 3.2109866 | H23: ='Balance Sheet'!H33 -> 3.32688 | I23: ='Balance Sheet'!I33 -> 3.4431917

Sheet Control
B2: Control & Scenario Engine
B4: Active scenario (1=Base, 2=Bull, 3=Bear) | E4: 1
B5: Current security price ($) | E5: 2.5
B6: Hedging master switch (1=ON, 0=OFF) | E6: 1
B8: Scenario factor table (driver deltas)
C9: Factor | D9: Base | E9: Bull | F9: Bear | G9: ACTIVE
B10: 1. Cap-rate shift vs base (bps) | D10: 0 | E10: -25 | F10: 50 | G10: =CHOOSE($E$4,D10,E10,F10) -> 0
B11: 2. Market rent-growth delta (% p.a.) | D11: 0 | E11: 0.01 | F11: -0.015 | G11: =CHOOSE($E$4,D11,E11,F11) -> 0
B12: 3. Cost-of-debt delta (% p.a.) | D12: 0 | E12: -0.0025 | F12: 0.0075 | G12: =CHOOSE($E$4,D12,E12,F12) -> 0
B13: Divestment executes (1/0) | D13: 0 | E13: 0 | F13: 0 | G13: =CHOOSE($E$4,D13,E13,F13) -> 0
B14: Buy-back executes (1/0) | D14: 1 | E14: 1 | F14: 0 | G14: =CHOOSE($E$4,D14,E14,F14) -> 1
B17: Headline outputs (live)
B18: NTA per security ($) | E18: ='Balance Sheet'!E33 -> 3.0070546
B19: Price / NTA | E19: =Control!E5/'Balance Sheet'!E33 -> 0.83137831
B20: Premium / (discount) to NTA | E20: =Control!E5/'Balance Sheet'!E33-1 -> -0.16862169
B21: FY26E FFO per security (cps) | E21: ='P&L'!E20 -> 17.335098
B22: FY26E AFFO per security (cps) | E22: ='P&L'!E22 -> 17.107757
B23: FY26E DPS (cps) | E23: ='P&L'!E24 -> 17.335098
B24: FY26E distribution yield | E24: ='P&L'!E24/100/Control!E5 -> 0.069340393
B25: FY26E FFO payout ratio | E25: ='P&L'!E25 -> 1
B26: FY26E AFFO payout ratio | E26: ='P&L'!E26 -> 1.0132888
B27: Gearing FY26E | E27: =Debt!E27 -> 0.32311803
B28: ICR FY26E | E28: =Debt!E30 -> 3.6932033
B29: Earnings-quality score (0-100) | E29: ='Earnings Quality'!E28 -> 72
B30: Blended valuation / security ($) | E30: =Valuation!E90 -> 2.6873443
B31: 5yr levered IRR | E31: ='Returns & Simulation'!E31 -> 0.13100608
B32: Implied up/(down)side to price | E32: =Valuation!E90/Control!E5-1 -> 0.074937724
B35: Governance & Takeover
B36: Management model | C36: INTERNALLY managed (VER Limited is the in-house RE) - no external manager
B37: Manager / platform | C37: Internal - management expense ratio just 30bp, among the lowest in the S&P/ASX 200 REIT index
B38: Manager stake | C38: No external manager and no blocking stake - the most open takeover register of the set
B39: Fee structure (earnings drag) | C39: Internal corporate cost ~$8.6m (30bp of GAV); no external base/performance fees to strip
B40: Takeover defensibility (poison pill) | C40: None. Internally managed, so a control change does not need a manager removed. With a ~14% discount to NTA, single-tenant Viva exposure and an open register, WPR is a genuine M&A / privatisation candidate (Viva Energy or infrastructure capital).
B41: Takeover assessment | C41: Takeover value = asset value plus a real control premium (no fee synergy because it is already internal). The catch is concentration: Viva Energy is effectively the whole rent roll, and the portfolio is ~6% over-rented, so a buyer underwrites fuel-retail and EV-transition risk.
B42: Major holders | C42: Open register; Viva Energy the dominant tenant. No strategic blocking holder.

Sheet Rates & Macro
B2: Rates & Macro - swap curve, bond forecast & provider consensus
B3: Running the swap curve now. Enter bank forecasts in the provider rows; Consensus = average of populated providers; ACTIVE feeds the model (cost of debt & risk-free for Ke).
C4: FY24A | D4: FY25A | E4: FY26E | F4: FY27E | G4: FY28E | H4: FY29E | I4: FY30E
B5: AUD 3M BBSW - floating base rate path (%)
B6: Swap-curve implied | C6: 0.0435 | D6: 0.0415 | E6: 0.036 | F6: 0.0365 | G6: 0.038 | H6: 0.039 | I6: 0.04
B7: Bank A (enter forecast)
B8: Bank B (enter forecast)
B9: Bank C (enter forecast)
B10: Consensus (avg of populated) | C10: =AVERAGE(C6:C9) -> 0.0435 | D10: =AVERAGE(D6:D9) -> 0.0415 | E10: =AVERAGE(E6:E9) -> 0.036 | F10: =AVERAGE(F6:F9) -> 0.0365 | G10: =AVERAGE(G6:G9) -> 0.038 | H10: =AVERAGE(H6:H9) -> 0.039 | I10: =AVERAGE(I6:I9) -> 0.04
B11: ACTIVE -> feeds cost of debt | C11: =C10 -> 0.0435 | D11: =D10 -> 0.0415 | E11: =E10 -> 0.036 | F11: =F10 -> 0.0365 | G11: =G10 -> 0.038 | H11: =H10 -> 0.039 | I11: =I10 -> 0.04
B13: ACGB 10-year yield - risk-free for cost of equity (%)
B14: Market / swap-implied | C14: 0.043 | D14: 0.043 | E14: 0.043 | F14: 0.0435 | G14: 0.044 | H14: 0.0445 | I14: 0.045
B15: Bank A (enter forecast)
B16: Bank B (enter forecast)
B17: Bank C (enter forecast)
B18: Consensus (avg of populated) | C18: =AVERAGE(C14:C17) -> 0.043 | D18: =AVERAGE(D14:D17) -> 0.043 | E18: =AVERAGE(E14:E17) -> 0.043 | F18: =AVERAGE(F14:F17) -> 0.0435 | G18: =AVERAGE(G14:G17) -> 0.044 | H18: =AVERAGE(H14:H17) -> 0.0445 | I18: =AVERAGE(I14:I17) -> 0.045
B19: ACTIVE -> feeds risk-free | C19: =C18 -> 0.043 | D19: =D18 -> 0.043 | E19: =E18 -> 0.043 | F19: =F18 -> 0.0435 | G19: =G18 -> 0.044 | H19: =H18 -> 0.0445 | I19: =I18 -> 0.045
B21: AUD swap rates by tenor (reference, %)
D22: 3yr | E22: 5yr | F22: 7yr | G22: 10yr
B23: Par swap rate | D23: 0.0365 | E23: 0.039 | F23: 0.041 | G23: 0.0435

Sheet Assumptions
B2: Assumptions & Operating Drivers
C4: FY24A | D4: FY25A | E4: FY26E | F4: FY27E | G4: FY28E | H4: FY29E | I4: FY30E
B5: Portfolio - Service Stations (FY25A base links from Asset Register)
B6: Service Stations passing NOI ($m) | C6: 158 | D6: 163.5 | E6: =D6*(1+E24)+E23 -> 166.15239 | F6: =E6*(1+F24)+F23 -> 169.82892 | G6: =F6*(1+G24)+G23 -> 174.50397 | H6: =G6*(1+H24)+H23 -> 179.19987 | I6: =H6*(1+I24)+I23 -> 183.91139
B7: Service Stations cap rate (WACR) | C7: 0.0576 | D7: 0.0566 | E7: =0.0566+Control!$G$10/10000 -> 0.0566 | F7: =E7 -> 0.0566 | G7: =F7 -> 0.0566 | H7: =G7 -> 0.0566 | I7: =H7 -> 0.0566
B8: Service Stations value ($m) | C8: =C6/C7 -> 2743.0556 | D8: =D6/D7 -> 2888.6926 | E8: =E6/E7 -> 2935.5546 | F8: =F6/F7 -> 3000.5109 | G8: =G6/G7 -> 3083.109 | H8: =H6/H7 -> 3166.0754 | I8: =I6/I7 -> 3249.3179
B10: Portfolio - (second sector - not used)
B11: n/a passing NOI ($m) | C11: 0 | D11: 0 | E11: =D11*(1+E24) -> 0 | F11: =E11*(1+F24) -> 0 | G11: =F11*(1+G24) -> 0 | H11: =G11*(1+H24) -> 0 | I11: =H11*(1+I24) -> 0
B12: n/a cap rate (WACR) | C12: 0.0576 | D12: 0.0566 | E12: =0.0566+Control!$G$10/10000 -> 0.0566 | F12: =E12 -> 0.0566 | G12: =F12 -> 0.0566 | H12: =G12 -> 0.0566 | I12: =H12 -> 0.0566
B13: n/a value ($m) | C13: =IF(C12=0,0,C11/C12) -> 0 | D13: =IF(D12=0,0,D11/D12) -> 0 | E13: =IF(E12=0,0,E11/E12) -> 0 | F13: =IF(F12=0,0,F11/F12) -> 0 | G13: =IF(G12=0,0,G11/G12) -> 0 | H13: =IF(H12=0,0,H11/H12) -> 0 | I13: =IF(I12=0,0,I11/I12) -> 0
B15: Divestment & redeployment
B16: Divestment gross value ($m) | E16: 0
B17: Minority interest retained (%) | E17: 0
B18: Selling / transaction costs (%) | E18: 0
B19: NOI removed on divestment ($m) | E19: 0
B20: Net cash proceeds to debt paydown ($m) | E20: 0
B21: Asset disposals at book ($m) | E21: 0
B22: Growth & redeployment
B23: Redeployment / development NOI add ($m) | C23: 0 | D23: 0 | E23: -2 | F23: -1 | G23: 0 | H23: 0 | I23: 0
B24: Like-for-like NOI growth (%) | C24: 0 | D24: 0 | E24: =E50 -> 0.028455 | F24: =F50 -> 0.028146 | G24: =G50 -> 0.027528 | H24: =H50 -> 0.02691 | I24: =I50 -> 0.026292
B25: Portfolio occupancy (%) | C25: 1 | D25: 1 | E25: 1 | F25: 1 | G25: 1 | H25: 1 | I25: 1
B27: Corporate, fees & capex
B28: Management fees ($m) | C28: 8.4 | D28: 8.6 | E28: =(E42)*$E$30 -> 8.8066639 | F28: =(F42)*$E$30 -> 9.0015327 | G28: =(G42)*$E$30 -> 9.2493269 | H28: =(H42)*$E$30 -> 9.4982263 | I28: =(I42)*$E$30 -> 9.7479537
B29: Corporate & admin ($m) | C29: 0.5 | D29: 0.5 | E29: 0.5 | F29: 0.5 | G29: 0.5 | H29: 0.5 | I29: 0.5
B30: Management fee rate (% of GAV) | E30: 0.003
B31: Maintenance capex ($m) | C31: 1 | D31: 1 | E31: 1 | F31: 1 | G31: 1 | H31: 1 | I31: 1
B32: Leasing costs & incentives ($m) | C32: 0.5 | D32: 0.5 | E32: 0.5 | F32: 0.5 | G32: 0.5 | H32: 0.5 | I32: 0.5
B33: Target payout ratio of EPU (%) | E33: 1
B34: Distributions & capital
B35: DPS declared (cps) [forecast = EPU x payout, capped <=100%] | C35: 16.48 | D35: 16.64 | E35: =MIN('P&L'!E20*$E$33,'P&L'!E20) -> 17.335098 | F35: =MIN('P&L'!F20*$E$33,'P&L'!F20) -> 17.618943 | G35: =MIN('P&L'!G20*$E$33,'P&L'!G20) -> 18.124481 | H35: =MIN('P&L'!H20*$E$33,'P&L'!H20) -> 18.68989 | I35: =MIN('P&L'!I20*$E$33,'P&L'!I20) -> 19.241979
B36: Tax-deferred proportion (%) | C36: 0.4 | D36: 0.4 | E36: 0.4 | F36: 0.4 | G36: 0.4 | H36: 0.4 | I36: 0.4
B37: On-market buy-back ($m) | C37: 0 | D37: 20 | E37: =8*Control!$G$14 -> 8 | F37: =0*Control!$G$14 -> 0 | G37: =0*Control!$G$14 -> 0 | H37: =0*Control!$G$14 -> 0 | I37: =0*Control!$G$14 -> 0
B38: Securities on issue - opening (m) | C38: 663 | D38: =C39 -> 663 | E38: =D39 -> 663 | F38: =E39 -> 659.8 | G38: =F39 -> 659.8 | H38: =G39 -> 659.8 | I38: =H39 -> 659.8
B39: Securities on issue - closing (m) | C39: =C38 -> 663 | D39: =D38 -> 663 | E39: =E38-E37/Control!$E$5 -> 659.8 | F39: =F38-F37/Control!$E$5 -> 659.8 | G39: =G38-G37/Control!$E$5 -> 659.8 | H39: =H38-H37/Control!$E$5 -> 659.8 | I39: =I38-I37/Control!$E$5 -> 659.8
B41: Portfolio totals (convenience links)
B42: Total portfolio value ($m) | C42: 2730 | D42: 2858 | E42: =E8+E13 -> 2935.5546 | F42: =F8+F13 -> 3000.5109 | G42: =G8+G13 -> 3083.109 | H42: =H8+H13 -> 3166.0754 | I42: =I8+I13 -> 3249.3179
B43: Total portfolio NOI ($m) | C43: =C6+C11 -> 158 | D43: =D6+D11 -> 163.5 | E43: =E6+E11 -> 166.15239 | F43: =F6+F11 -> 169.82892 | G43: =G6+G11 -> 174.50397 | H43: =H6+H11 -> 179.19987 | I43: =I6+I11 -> 183.91139
B44: Blended WACR (%) | C44: =C43/C42 -> 0.057875458 | D44: =D43/D42 -> 0.057207838 | E44: =E43/E42 -> 0.0566 | F44: =F43/F42 -> 0.0566 | G44: =G43/G42 -> 0.0566 | H44: =H43/H42 -> 0.0566 | I44: =I43/I42 -> 0.0566
B46: Lease-expiry NOI build (analyst - drives sector NOI)
B47: Contracted rent escalation (% p.a.) | E47: 0.03 | F47: 0.03 | G47: 0.03 | H47: 0.03 | I47: 0.03
...

Sheet Asset Register
B2: Asset Register - current portfolio (latest basis)
B3: Populate asset-by-asset over time. Sector subtotals (SUMIF) feed Assumptions as the FY25A base. Set Divest?=1 to include an asset in the divestment. Blue=input, green=link.
B6: Asset | C6: Sector | D6: State | E6: Anchor / key tenant | F6: Passing NOI ($m) | G6: Cap rate | H6: Value ($m) | I6: WALE (yrs) | J6: Occ % | K6: Divest?
B7: Metro service stations (VIC/NSW/QLD) | C7: Service Stations | D7: VIC/NSW/QLD | E7: Viva Energy (Shell/OTR) | F7: 78 | G7: 0.0555 | H7: =F7/G7 -> 1405.4054 | I7: 8.6 | J7: 1 | K7: 0
B8: Regional & highway sites | C8: Service Stations | D8: National | E8: Viva Energy (Shell/Liberty) | F8: 62 | G8: 0.058 | H8: =F8/G8 -> 1068.9655 | I8: 8.2 | J8: 1 | K8: 0
B9: Convenience & non-core | C9: Service Stations | D9: Various | E9: Viva/other operators | F9: 23.5 | G9: 0.06 | H9: =F9/G9 -> 391.66667 | I9: 7.5 | J9: 0.99 | K9: 0
B11: Service Stations subtotal | F11: =SUMIF($C$7:$C$9,"Service Stations",$F$7:$F$9) -> 163.5 | G11: =IF(H11=0,0,F11/H11) -> 0.057047403 | H11: =SUMIF($C$7:$C$9,"Service Stations",$H$7:$H$9) -> 2866.0376
B12: (no second sector) | F12: =SUMIF($C$7:$C$9,"__none__",$F$7:$F$9) -> 0 | G12: =IF(H12=0,0,F12/H12) -> 0 | H12: =SUMIF($C$7:$C$9,"__none__",$H$7:$H$9) -> 0
B13: Total portfolio | F13: =SUM(F11:F12) -> 163.5 | G13: =F13/H13 -> 0.057047403 | H13: =SUM(H11:H12) -> 2866.0376
B14: Divestment-flagged (Divest?=1) | F14: =SUMIF($K$7:$K$9,1,$F$7:$F$9) -> 0 | H14: =SUMIF($K$7:$K$9,1,$H$7:$H$9) -> 0

Sheet Lease Expiry
B2: Lease Expiry & Re-leasing - cash flow impact
C4: FY24A | D4: FY25A | E4: FY26E | F4: FY27E | G4: FY28E | H4: FY29E | I4: FY30E
B5: Portfolio lease metrics
B6: WALE (years) | E6: 8.4
B7: Occupancy (% of income) | E7: 1
B8: Vacant (% of income) | E8: 0
B9: Contracted rent escalation (% p.a.) | E9: =Assumptions!E47 -> 0.03
B10: Market re-leasing reversion on expiry (%) | E10: =Assumptions!E49 -> -0.03
B12: Lease expiry profile (% of passing income expiring in year)
B13: Expiring in year (% of income) | C13: 0 | E13: =Assumptions!E48 -> 0.05 | F13: =Assumptions!F48 -> 0.06 | G13: =Assumptions!G48 -> 0.08 | H13: =Assumptions!H48 -> 0.1 | I13: =Assumptions!I48 -> 0.12
B14: Expiring beyond FY30 (% of income) | E14: 0.59
B15: Cumulative % expired (incl vacant) | C15: 0 | E15: =D15+E13 -> 0.05 | F15: =E15+F13 -> 0.11 | G15: =F15+G13 -> 0.19 | H15: =G15+H13 -> 0.29 | I15: =H15+I13 -> 0.41
B17: Re-leasing cash flow impact ($m)
B18: Portfolio NOI - opening ($m) | E18: =Assumptions!D43 -> 163.5 | F18: =Assumptions!E43 -> 166.15239 | G18: =Assumptions!F43 -> 169.82892 | H18: =Assumptions!G43 -> 174.50397 | I18: =Assumptions!H43 -> 179.19987
B19: Income up for renewal in year ($m) | E19: =E18*E13 -> 8.175 | F19: =F18*F13 -> 9.9691436 | G19: =G18*G13 -> 13.586313 | H19: =H18*H13 -> 17.450397 | I19: =I18*I13 -> 21.503984
B20: (+) Reversion uplift captured ($m) | E20: =E19*Assumptions!E49 -> -0.24525 | F20: =F19*Assumptions!F49 -> -0.29907431 | G20: =G19*Assumptions!G49 -> -0.4075894 | H20: =H19*Assumptions!H49 -> -0.5235119 | I20: =I19*Assumptions!I49 -> -0.64511953
B21: (+) Contracted escalation on retained income ($m) | E21: =(E18-E19)*Assumptions!E47 -> 4.65975 | F21: =(F18-F19)*Assumptions!F47 -> 4.6854975 | G21: =(G18-G19)*Assumptions!G47 -> 4.6872781 | H21: =(H18-H19)*Assumptions!H47 -> 4.7116071 | I21: =(I18-I19)*Assumptions!I47 -> 4.7308766
B22: Net like-for-like NOI growth ($m) | E22: =E20+E21 -> 4.4145 | F22: =F20+F21 -> 4.3864232 | G22: =G20+G21 -> 4.2796887 | H22: =H20+H21 -> 4.1880952 | I22: =I20+I21 -> 4.085757
B23: Effective like-for-like NOI growth (%) | E23: =Assumptions!E50 -> 0.028455 | F23: =Assumptions!F50 -> 0.028146 | G23: =Assumptions!G50 -> 0.027528 | H23: =Assumptions!H50 -> 0.02691 | I23: =Assumptions!I50 -> 0.026292
B24: (+) Development / acquisition NOI ($m) | E24: =Assumptions!E23 -> -2 | F24: =Assumptions!F23 -> -1 | G24: =Assumptions!G23 -> 0 | H24: =Assumptions!H23 -> 0 | I24: =Assumptions!I23 -> 0
B25: Total NOI growth in year ($m) | E25: =E22+E24 -> 2.4145 | F25: =F22+F24 -> 3.3864232 | G25: =G22+G24 -> 4.2796887 | H25: =H22+H24 -> 4.1880952 | I25: =I22+I24 -> 4.085757

Sheet Debt
B2: Debt & Hedging Module
B3: Hedging master switch = Control!E6. Interest on average net debt (ex-revolver) -> non-circular. Revolver funds any cash shortfall.
C4: FY24A | D4: FY25A | E4: FY26E | F4: FY27E | G4: FY28E | H4: FY29E | I4: FY30E
B5: Facility & net-debt schedule
B6: Facility limit ($m) | C6: 1150 | D6: 1150 | E6: 1150 | F6: 1150 | G6: 1150 | H6: 1150 | I6: 1150
B7: Opening net debt ($m) | C7: 935 | D7: =C12 -> 900 | E7: =D12 -> 935 | F7: =E12 -> 949.5 | G7: =F12 -> 956 | H7: =G12 -> 962.5 | I7: =H12 -> 969
B8: (less) Net divestment proceeds ($m) | C8: =Assumptions!C20 -> 0 | D8: =Assumptions!D20 -> 0 | E8: =Assumptions!E20 -> 0 | F8: =Assumptions!F20 -> 0 | G8: =Assumptions!G20 -> 0 | H8: =Assumptions!H20 -> 0 | I8: =Assumptions!I20 -> 0
B9: (less) Scheduled amortisation ($m) | C9: 0 | D9: 0 | E9: 0 | F9: 0 | G9: 0 | H9: 0 | I9: 0
B10: (add) Growth / redeployment capex drawn ($m) | C10: 0 | D10: 0 | E10: 5 | F10: 5 | G10: 5 | H10: 5 | I10: 5
B11: (add) Revolver draw to fund cash shortfall ($m) | C11: ='Cash Flow'!C12 -> 0 | D11: ='Cash Flow'!D12 -> 21.0856 | E11: ='Cash Flow'!E12 -> 9.5 | F11: ='Cash Flow'!F12 -> 1.5 | G11: ='Cash Flow'!G12 -> 1.5 | H11: ='Cash Flow'!H12 -> 1.5 | I11: ='Cash Flow'!I12 -> 1.5
B12: Closing net debt ($m) | C12: 900 | D12: 935 | E12: =E7-E8-E9+E10+E11 -> 949.5 | F12: =F7-F8-F9+F10+F11 -> 956 | G12: =G7-G8-G9+G10+G11 -> 962.5 | H12: =H7-H8-H9+H10+H11 -> 969 | I12: =I7-I8-I9+I10+I11 -> 975.5
B13: Average net debt ($m) | C13: =(C7+C12)/2 -> 917.5 | D13: =(D7+D12)/2 -> 917.5 | E13: =(E7+E12)/2 -> 942.25 | F13: =(F7+F12)/2 -> 952.75 | G13: =(G7+G12)/2 -> 959.25 | H13: =(H7+H12)/2 -> 965.75 | I13: =(I7+I12)/2 -> 972.25
B15: Hedging & cost of debt
B16: Floating base rate - BBSW (%) [forecast from Rates & Macro] | C16: 0.0435 | D16: 0.0415 | E16: ='Rates & Macro'!E11 -> 0.036 | F16: ='Rates & Macro'!F11 -> 0.0365 | G16: ='Rates & Macro'!G11 -> 0.038 | H16: ='Rates & Macro'!H11 -> 0.039 | I16: ='Rates & Macro'!I11 -> 0.04
B17: Credit margin (%) | C17: 0.011 | D17: 0.011 | E17: 0.011 | F17: 0.011 | G17: 0.011 | H17: 0.011 | I17: 0.011
B18: All-in floating rate (%) | C18: =C16+C17 -> 0.0545 | D18: =D16+D17 -> 0.0525 | E18: =E16+E17 -> 0.047 | F18: =F16+F17 -> 0.0475 | G18: =G16+G17 -> 0.049 | H18: =H16+H17 -> 0.05 | I18: =I16+I17 -> 0.051
B19: Hedge ratio - input (%) | C19: 0.9 | D19: 0.9 | E19: 0.85 | F19: 0.8 | G19: 0.75 | H19: 0.7 | I19: 0.65
B20: Effective hedge ratio (%) [x master switch] | C20: =C19*Control!$E$6 -> 0.9 | D20: =D19*Control!$E$6 -> 0.9 | E20: =E19*Control!$E$6 -> 0.85 | F20: =F19*Control!$E$6 -> 0.8 | G20: =G19*Control!$E$6 -> 0.75 | H20: =H19*Control!$E$6 -> 0.7 | I20: =I19*Control!$E$6 -> 0.65
B21: Hedged (swap) all-in rate (%) | C21: 0.041 | D21: 0.044 | E21: 0.045 | F21: 0.046 | G21: 0.0465 | H21: 0.0465 | I21: 0.0465
B22: Blended cost of debt (%) | C22: =C20*C21+(1-C20)*C18 -> 0.04235 | D22: =D20*D21+(1-D20)*D18 -> 0.04485 | E22: =E20*E21+(1-E20)*E18 -> 0.0453 | F22: =F20*F21+(1-F20)*F18 -> 0.0463 | G22: =G20*G21+(1-G20)*G18 -> 0.047125 | H22: =H20*H21+(1-H20)*H18 -> 0.04755 | I22: =I20*I21+(1-I20)*I18 -> 0.048075
B23: Interest expense ($m) [avg debt, ex-revolver] | C23: 40 | D23: 44 | E23: =E22*((E7+(E7-E8-E9+E10))/2) -> 42.46875 | F23: =F22*((F7+(F7-F8-F9+F10))/2) -> 44.0776 | G23: =G22*((G7+(G7-G8-G9+G10))/2) -> 45.169312 | H23: =H22*((H7+(H7-H8-H9+H10))/2) -> 45.88575 | I23: =I22*((I7+(I7-I8-I9+I10))/2) -> 46.704862
B25: Gearing & coverage
B26: Total tangible assets ($m) | C26: =Assumptions!C42+'Cash Flow'!C13 -> 2733.3376 | D26: =Assumptions!D42+'Cash Flow'!D13 -> 2861 | E26: =Assumptions!E42+'Cash Flow'!E13 -> 2938.5546 | F26: =Assumptions!F42+'Cash Flow'!F13 -> 3003.5109 | G26: =Assumptions!G42+'Cash Flow'!G13 -> 3086.109 | H26: =Assumptions!H42+'Cash Flow'!H13 -> 3169.0754 | I26: =Assumptions!I42+'Cash Flow'!I13 -> 3252.3179
B27: Gearing (net debt / total assets) | C27: 0.31 | D27: 0.327 | E27: =E12/E26 -> 0.32311803 | F27: =F12/F26 -> 0.31829417 | G27: =G12/G26 -> 0.3118814 | H27: =H12/H26 -> 0.30576741 | I27: =I12/I26 -> 0.29993993
B28: Facility headroom ($m) | C28: =C6-C12 -> 250 | D28: =D6-D12 -> 215 | E28: =E6-E12 -> 200.5 | F28: =F6-F12 -> 194 | G28: =G6-G12 -> 187.5 | H28: =H6-H12 -> 181 | I28: =I6-I12 -> 174.5
B29: EBIT for ICR ($m) | C29: =Assumptions!C43-Assumptions!C28-Assumptions!C29 -> 149.1 | D29: =Assumptions!D43-Assumptions!D28-Assumptions!D29 -> 154.4 | E29: =Assumptions!E43-Assumptions!E28-Assumptions!E29 -> 156.84573 | F29: =Assumptions!F43-Assumptions!F28-Assumptions!F29 -> 160.32738 | G29: =Assumptions!G43-Assumptions!G28-Assumptions!G29 -> 164.75464 | H29: =Assumptions!H43-Assumptions!H28-Assumptions!H29 -> 169.20164 | I29: =Assumptions!I43-Assumptions!I28-Assumptions!I29 -> 173.66344
B30: Interest cover ratio (ICR, x) | C30: =C29/C23 -> 3.7275 | D30: =D29/D23 -> 3.5090909 | E30: =E29/E23 -> 3.6932033 | F30: =F29/F23 -> 3.6373892 | G30: =G29/G23 -> 3.6474906 | H30: =H29/H23 -> 3.6874551 | I30: =I29/I23 -> 3.718316
B32: Debt maturity ladder ($m drawn by expiry) - WADM ~3.8 yrs, first maturity FY27
D33: FY26 | E33: FY27 | F33: FY28 | G33: FY29 | H33: FY30 | I33: Beyond
B34: Debt maturing ($m) | D34: 50 | E34: 300 | F34: 300 | G34: 185 | H34: 100 | I34: 0
B35: Total drawn (ladder, $m) | D35: =SUM(D34:I34) -> 935
B36: Assumed refinance margin (%) | E36: 0.011

Sheet P&L
B2: Profit & Loss - FFO / AFFO / Statutory
C4: FY24A | D4: FY25A | E4: FY26E | F4: FY27E | G4: FY28E | H4: FY29E | I4: FY30E
B5: Funds From Operations (FFO)
B6: Net property income (NOI) | C6: =Assumptions!C43 -> 158 | D6: =Assumptions!D43 -> 163.5 | E6: =Assumptions!E43 -> 166.15239 | F6: =Assumptions!F43 -> 169.82892 | G6: =Assumptions!G43 -> 174.50397 | H6: =Assumptions!H43 -> 179.19987 | I6: =Assumptions!I43 -> 183.91139
B7: (less) Management fees | C7: =Assumptions!C28 -> 8.4 | D7: =Assumptions!D28 -> 8.6 | E7: =Assumptions!E28 -> 8.8066639 | F7: =Assumptions!F28 -> 9.0015327 | G7: =Assumptions!G28 -> 9.2493269 | H7: =Assumptions!H28 -> 9.4982263 | I7: =Assumptions!I28 -> 9.7479537
B8: (less) Corporate & admin | C8: =Assumptions!C29 -> 0.5 | D8: =Assumptions!D29 -> 0.5 | E8: =Assumptions!E29 -> 0.5 | F8: =Assumptions!F29 -> 0.5 | G8: =Assumptions!G29 -> 0.5 | H8: =Assumptions!H29 -> 0.5 | I8: =Assumptions!I29 -> 0.5
B9: EBIT / distributable operating profit | C9: =C6-C7-C8 -> 149.1 | D9: =D6-D7-D8 -> 154.4 | E9: =E6-E7-E8 -> 156.84573 | F9: =F6-F7-F8 -> 160.32738 | G9: =G6-G7-G8 -> 164.75464 | H9: =H6-H7-H8 -> 169.20164 | I9: =I6-I7-I8 -> 173.66344
B10: (less) Net finance costs | C10: =Debt!C23 -> 40 | D10: =Debt!D23 -> 44 | E10: =Debt!E23 -> 42.46875 | F10: =Debt!F23 -> 44.0776 | G10: =Debt!G23 -> 45.169312 | H10: =Debt!H23 -> 45.88575 | I10: =Debt!I23 -> 46.704862
B11: Other recurring income / (costs) | C11: 0 | D11: 0 | E11: 0 | F11: 0 | G11: 0 | H11: 0 | I11: 0
B12: FFO ($m) | C12: =C9-C10+C11 -> 109.1 | D12: =D9-D10+D11 -> 110.4 | E12: =E9-E10+E11 -> 114.37698 | F12: =F9-F10+F11 -> 116.24978 | G12: =G9-G10+G11 -> 119.58533 | H12: =H9-H10+H11 -> 123.31589 | I12: =I9-I10+I11 -> 126.95858
B14: Adjusted FFO (AFFO)
B15: FFO ($m) | C15: =C12 -> 109.1 | D15: =D12 -> 110.4 | E15: =E12 -> 114.37698 | F15: =F12 -> 116.24978 | G15: =G12 -> 119.58533 | H15: =H12 -> 123.31589 | I15: =I12 -> 126.95858
B16: (less) Maintenance capex | C16: =Assumptions!C31 -> 1 | D16: =Assumptions!D31 -> 1 | E16: =Assumptions!E31 -> 1 | F16: =Assumptions!F31 -> 1 | G16: =Assumptions!G31 -> 1 | H16: =Assumptions!H31 -> 1 | I16: =Assumptions!I31 -> 1
B17: (less) Leasing costs & incentives | C17: =Assumptions!C32 -> 0.5 | D17: =Assumptions!D32 -> 0.5 | E17: =Assumptions!E32 -> 0.5 | F17: =Assumptions!F32 -> 0.5 | G17: =Assumptions!G32 -> 0.5 | H17: =Assumptions!H32 -> 0.5 | I17: =Assumptions!I32 -> 0.5
B18: AFFO ($m) | C18: =C15-C16-C17 -> 107.6 | D18: =D15-D16-D17 -> 108.9 | E18: =E15-E16-E17 -> 112.87698 | F18: =F15-F16-F17 -> 114.74978 | G18: =G15-G16-G17 -> 118.08533 | H18: =H15-H16-H17 -> 121.81589 | I18: =I15-I16-I17 -> 125.45858
B19: Per-security & distributions
B20: FFO per security (cps) | C20: =C12/Assumptions!C39*100 -> 16.455505 | D20: =D12/Assumptions!D39*100 -> 16.651584 | E20: =E12/Assumptions!E39*100 -> 17.335098 | F20: =F12/Assumptions!F39*100 -> 17.618943 | G20: =G12/Assumptions!G39*100 -> 18.124481 | H20: =H12/Assumptions!H39*100 -> 18.68989 | I20: =I12/Assumptions!I39*100 -> 19.241979
B22: AFFO per security (cps) | C22: =C18/Assumptions!C39*100 -> 16.229261 | D22: =D18/Assumptions!D39*100 -> 16.425339 | E22: =E18/Assumptions!E39*100 -> 17.107757 | F22: =F18/Assumptions!F39*100 -> 17.391601 | G22: =G18/Assumptions!G39*100 -> 17.89714 | H22: =H18/Assumptions!H39*100 -> 18.462548 | I22: =I18/Assumptions!I39*100 -> 19.014637
B24: DPS declared (cps) | C24: =Assumptions!C35 -> 16.48 | D24: =Assumptions!D35 -> 16.64 | E24: =Assumptions!E35 -> 17.335098 | F24: =Assumptions!F35 -> 17.618943 | G24: =Assumptions!G35 -> 18.124481 | H24: =Assumptions!H35 -> 18.68989 | I24: =Assumptions!I35 -> 19.241979
B25: FFO payout ratio | C25: =(C24/100*Assumptions!C39)/C12 -> 1.0014885 | D25: =(D24/100*Assumptions!D39)/D12 -> 0.99930435 | E25: =(E24/100*Assumptions!E39)/E12 -> 1 | F25: =(F24/100*Assumptions!F39)/F12 -> 1 | G25: =(G24/100*Assumptions!G39)/G12 -> 1 | H25: =(H24/100*Assumptions!H39)/H12 -> 1 | I25: =(I24/100*Assumptions!I39)/I12 -> 1
B26: AFFO payout ratio | C26: =(C24/100*Assumptions!C39)/C18 -> 1.0154498 | D26: =(D24/100*Assumptions!D39)/D18 -> 1.0130689 | E26: =(E24/100*Assumptions!E39)/E18 -> 1.0132888 | F26: =(F24/100*Assumptions!F39)/F18 -> 1.0130719 | G26: =(G24/100*Assumptions!G39)/G18 -> 1.0127027 | H26: =(H24/100*Assumptions!H39)/H18 -> 1.0123137 | I26: =(I24/100*Assumptions!I39)/I18 -> 1.0119561
B27: Distributions paid ($m) | C27: =C24/100*Assumptions!C39 -> 109.2624 | D27: =D24/100*Assumptions!D39 -> 110.3232 | E27: =E24/100*Assumptions!E39 -> 114.37698 | F27: =F24/100*Assumptions!F39 -> 116.24978 | G27: =G24/100*Assumptions!G39 -> 119.58533 | H27: =H24/100*Assumptions!H39 -> 123.31589 | I27: =I24/100*Assumptions!I39 -> 126.95858
B29: Statutory reconciliation
B30: FFO ($m) | C30: =C12 -> 109.1 | D30: =D12 -> 110.4 | E30: =E12 -> 114.37698 | F30: =F12 -> 116.24978 | G30: =G12 -> 119.58533 | H30: =H12 -> 123.31589 | I30: =I12 -> 126.95858
B31: (+/-) Property revaluation gain / (loss) | C31: -8 | D31: =Assumptions!D42-Assumptions!C42+Assumptions!D21 -> 128 | E31: =Assumptions!E42-Assumptions!D42+Assumptions!E21 -> 77.554638 | F31: =Assumptions!F42-Assumptions!E42+Assumptions!F21 -> 64.956276 | G31: =Assumptions!G42-Assumptions!F42+Assumptions!G21 -> 82.598064 | H31: =Assumptions!H42-Assumptions!G42+Assumptions!H21 -> 82.966463 | I31: =Assumptions!I42-Assumptions!H42+Assumptions!I21 -> 83.242455
B32: (less) Straight-line / incentive amortisation | C32: 1 | D32: 1.2 | E32: 1 | F32: 0.9 | G32: 0.8 | H32: 0.8 | I32: 0.8
B33: (+/-) Derivative mark-to-market | C33: 0 | D33: 0 | E33: 0 | F33: 0 | G33: 0 | H33: 0 | I33: 0
B34: (less) Transaction / divestment costs (one-off) | C34: 0 | D34: 0 | E34: 0 | F34: 0 | G34: 0 | H34: 0 | I34: 0
B35: Statutory net profit / (loss) ($m) | C35: =C30+C31-C32+C33-C34 -> 100.1 | D35: =D30+D31-D32+D33-D34 -> 237.2 | E35: =E30+E31-E32+E33-E34 -> 190.93162 | F35: =F30+F31-F32+F33-F34 -> 180.30606 | G35: =G30+G31-G32+G33-G34 -> 201.38339 | H35: =H30+H31-H32+H33-H34 -> 205.48236 | I35: =I30+I31-I32+I33-I34 -> 209.40103

Sheet Earnings Quality
B2: Earnings Quality - true cash, coverage, scorecard
C4: FY24A | D4: FY25A | E4: FY26E | F4: FY27E | G4: FY28E | H4: FY29E | I4: FY30E
B5: Cash vs accounting earnings
B6: Statutory net profit / (loss) ($m) | C6: ='P&L'!C35 -> 100.1 | D6: ='P&L'!D35 -> 237.2 | E6: ='P&L'!E35 -> 190.93162 | F6: ='P&L'!F35 -> 180.30606 | G6: ='P&L'!G35 -> 201.38339 | H6: ='P&L'!H35 -> 205.48236 | I6: ='P&L'!I35 -> 209.40103
B7: FFO ($m) | C7: ='P&L'!C12 -> 109.1 | D7: ='P&L'!D12 -> 110.4 | E7: ='P&L'!E12 -> 114.37698 | F7: ='P&L'!F12 -> 116.24978 | G7: ='P&L'!G12 -> 119.58533 | H7: ='P&L'!H12 -> 123.31589 | I7: ='P&L'!I12 -> 126.95858
B8: AFFO - true cash ($m) | C8: ='P&L'!C18 -> 107.6 | D8: ='P&L'!D18 -> 108.9 | E8: ='P&L'!E18 -> 112.87698 | F8: ='P&L'!F18 -> 114.74978 | G8: ='P&L'!G18 -> 118.08533 | H8: ='P&L'!H18 -> 121.81589 | I8: ='P&L'!I18 -> 125.45858
B9: Recurring NOI ($m) | C9: =Assumptions!C43 -> 158 | D9: =Assumptions!D43 -> 163.5 | E9: =Assumptions!E43 -> 166.15239 | F9: =Assumptions!F43 -> 169.82892 | G9: =Assumptions!G43 -> 174.50397 | H9: =Assumptions!H43 -> 179.19987 | I9: =Assumptions!I43 -> 183.91139
B10: Non-cash / one-off items in statutory ($m) | C10: ='P&L'!C31-'P&L'!C32+'P&L'!C33-'P&L'!C34 -> -9 | D10: ='P&L'!D31-'P&L'!D32+'P&L'!D33-'P&L'!D34 -> 126.8 | E10: ='P&L'!E31-'P&L'!E32+'P&L'!E33-'P&L'!E34 -> 76.554638 | F10: ='P&L'!F31-'P&L'!F32+'P&L'!F33-'P&L'!F34 -> 64.056276 | G10: ='P&L'!G31-'P&L'!G32+'P&L'!G33-'P&L'!G34 -> 81.798064 | H10: ='P&L'!H31-'P&L'!H32+'P&L'!H33-'P&L'!H34 -> 82.166463 | I10: ='P&L'!I31-'P&L'!I32+'P&L'!I33-'P&L'!I34 -> 82.442455
B12: Quality ratios
B13: AFFO / FFO (cash conversion) | C13: =C8/C7 -> 0.98625115 | D13: =D8/D7 -> 0.98641304 | E13: =E8/E7 -> 0.98688547 | F13: =F8/F7 -> 0.98709675 | G13: =G8/G7 -> 0.98745666 | H13: =H8/H7 -> 0.98783612 | I13: =I8/I7 -> 0.98818512
B14: FFO payout ratio | C14: ='P&L'!C25 -> 1.0014885 | D14: ='P&L'!D25 -> 0.99930435 | E14: ='P&L'!E25 -> 1 | F14: ='P&L'!F25 -> 1 | G14: ='P&L'!G25 -> 1 | H14: ='P&L'!H25 -> 1 | I14: ='P&L'!I25 -> 1
B15: AFFO payout ratio | C15: ='P&L'!C26 -> 1.0154498 | D15: ='P&L'!D26 -> 1.0130689 | E15: ='P&L'!E26 -> 1.0132888 | F15: ='P&L'!F26 -> 1.0130719 | G15: ='P&L'!G26 -> 1.0127027 | H15: ='P&L'!H26 -> 1.0123137 | I15: ='P&L'!I26 -> 1.0119561
B16: AFFO distribution cover (x) | C16: =C8/'P&L'!C27 -> 0.98478525 | D16: =D8/'P&L'!D27 -> 0.98709972 | E16: =E8/'P&L'!E27 -> 0.98688547 | F16: =F8/'P&L'!F27 -> 0.98709675 | G16: =G8/'P&L'!G27 -> 0.98745666 | H16: =H8/'P&L'!H27 -> 0.98783612 | I16: =I8/'P&L'!I27 -> 0.98818512
B17: Distribution surplus / (shortfall) vs FFO ($m) | C17: =C7-'P&L'!C27 -> -0.1624 | D17: =D7-'P&L'!D27 -> 0.0768 | E17: =E7-'P&L'!E27 -> 0 | F17: =F7-'P&L'!F27 -> 0 | G17: =G7-'P&L'!G27 -> 0 | H17: =H7-'P&L'!H27 -> 0 | I17: =I7-'P&L'!I27 -> 0
B18: Tax-deferred proportion (%) | C18: =Assumptions!C36 -> 0.4 | D18: =Assumptions!D36 -> 0.4 | E18: =Assumptions!E36 -> 0.4 | F18: =Assumptions!F36 -> 0.4 | G18: =Assumptions!G36 -> 0.4 | H18: =Assumptions!H36 -> 0.4 | I18: =Assumptions!I36 -> 0.4
B19: Like-for-like NOI growth (%) | C19: =Assumptions!C24 -> 0 | D19: =Assumptions!D24 -> 0 | E19: =Assumptions!E24 -> 0.028455 | F19: =Assumptions!F24 -> 0.028146 | G19: =Assumptions!G24 -> 0.027528 | H19: =Assumptions!H24 -> 0.02691 | I19: =Assumptions!I24 -> 0.026292
B20: Operating cash flow cover of distribution (x) | C20: =('P&L'!C12-Assumptions!C32)/'P&L'!C27 -> 0.99393753 | D20: =('P&L'!D12-Assumptions!D32)/'P&L'!D27 -> 0.996164 | E20: =('P&L'!E12-Assumptions!E32)/'P&L'!E27 -> 0.99562849 | F20: =('P&L'!F12-Assumptions!F32)/'P&L'!F27 -> 0.99569892 | G20: =('P&L'!G12-Assumptions!G32)/'P&L'!G27 -> 0.99581889 | H20: =('P&L'!H12-Assumptions!H32)/'P&L'!H27 -> 0.99594537 | I20: =('P&L'!I12-Assumptions!I32)/'P&L'!I27 -> 0.99606171
B21: Earnings-quality scorecard (each 0-20; FY26E drives Control)
B22: AFFO covers distribution (>=1.0x) | C22: =IF(C16>=1,20,IF(C16>=0.9,12,IF(C16>=0.8,6,0))) -> 12 | D22: =IF(D16>=1,20,IF(D16>=0.9,12,IF(D16>=0.8,6,0))) -> 12 | E22: =IF(E16>=1,20,IF(E16>=0.9,12,IF(E16>=0.8,6,0))) -> 12 | F22: =IF(F16>=1,20,IF(F16>=0.9,12,IF(F16>=0.8,6,0))) -> 12 | G22: =IF(G16>=1,20,IF(G16>=0.9,12,IF(G16>=0.8,6,0))) -> 12 | H22: =IF(H16>=1,20,IF(H16>=0.9,12,IF(H16>=0.8,6,0))) -> 12 | I22: =IF(I16>=1,20,IF(I16>=0.9,12,IF(I16>=0.8,6,0))) -> 12
B23: FFO payout sustainable (<=100%) | C23: =IF(C14<=1,20,IF(C14<=1.1,12,IF(C14<=1.25,6,0))) -> 12 | D23: =IF(D14<=1,20,IF(D14<=1.1,12,IF(D14<=1.25,6,0))) -> 20 | E23: =IF(E14<=1,20,IF(E14<=1.1,12,IF(E14<=1.25,6,0))) -> 20 | F23: =IF(F14<=1,20,IF(F14<=1.1,12,IF(F14<=1.25,6,0))) -> 20 | G23: =IF(G14<=1,20,IF(G14<=1.1,12,IF(G14<=1.25,6,0))) -> 20 | H23: =IF(H14<=1,20,IF(H14<=1.1,12,IF(H14<=1.25,6,0))) -> 20 | I23: =IF(I14<=1,20,IF(I14<=1.1,12,IF(I14<=1.25,6,0))) -> 20
B24: Like-for-like NOI growth healthy | C24: =IF(C19>=0.03,20,IF(C19>=0.02,14,IF(C19>0,8,0))) -> 0 | D24: =IF(D19>=0.03,20,IF(D19>=0.02,14,IF(D19>0,8,0))) -> 0 | E24: =IF(E19>=0.03,20,IF(E19>=0.02,14,IF(E19>0,8,0))) -> 14 | F24: =IF(F19>=0.03,20,IF(F19>=0.02,14,IF(F19>0,8,0))) -> 14 | G24: =IF(G19>=0.03,20,IF(G19>=0.02,14,IF(G19>0,8,0))) -> 14 | H24: =IF(H19>=0.03,20,IF(H19>=0.02,14,IF(H19>0,8,0))) -> 14 | I24: =IF(I19>=0.03,20,IF(I19>=0.02,14,IF(I19>0,8,0))) -> 14
B25: Gearing within band (<=40%) | C25: =IF(Debt!C27<=0.35,20,IF(Debt!C27<=0.4,12,IF(Debt!C27<=0.45,5,0))) -> 20 | D25: =IF(Debt!D27<=0.35,20,IF(Debt!D27<=0.4,12,IF(Debt!D27<=0.45,5,0))) -> 20 | E25: =IF(Debt!E27<=0.35,20,IF(Debt!E27<=0.4,12,IF(Debt!E27<=0.45,5,0))) -> 20 | F25: =IF(Debt!F27<=0.35,20,IF(Debt!F27<=0.4,12,IF(Debt!F27<=0.45,5,0))) -> 20 | G25: =IF(Debt!G27<=0.35,20,IF(Debt!G27<=0.4,12,IF(Debt!G27<=0.45,5,0))) -> 20 | H25: =IF(Debt!H27<=0.35,20,IF(Debt!H27<=0.4,12,IF(Debt!H27<=0.45,5,0))) -> 20 | I25: =IF(Debt!I27<=0.35,20,IF(Debt!I27<=0.4,12,IF(Debt!I27<=0.45,5,0))) -> 20
B26: Low reliance on revaluation / one-offs | C26: =IF(ABS(C10)<=2,20,IF(ABS(C10)<=8,12,6)) -> 6 | D26: =IF(ABS(D10)<=2,20,IF(ABS(D10)<=8,12,6)) -> 6 | E26: =IF(ABS(E10)<=2,20,IF(ABS(E10)<=8,12,6)) -> 6 | F26: =IF(ABS(F10)<=2,20,IF(ABS(F10)<=8,12,6)) -> 6 | G26: =IF(ABS(G10)<=2,20,IF(ABS(G10)<=8,12,6)) -> 6 | H26: =IF(ABS(H10)<=2,20,IF(ABS(H10)<=8,12,6)) -> 6 | I26: =IF(ABS(I10)<=2,20,IF(ABS(I10)<=8,12,6)) -> 6
B28: TOTAL earnings-quality score (0-100) | C28: =SUM(C22:C26) -> 50 | D28: =SUM(D22:D26) -> 58 | E28: =SUM(E22:E26) -> 72 | F28: =SUM(F22:F26) -> 72 | G28: =SUM(G22:G26) -> 72 | H28: =SUM(H22:H26) -> 72 | I28: =SUM(I22:I26) -> 72

Sheet Cash Flow
B2: Cash Flow (cash-based)
C4: FY24A | D4: FY25A | E4: FY26E | F4: FY27E | G4: FY28E | H4: FY29E | I4: FY30E
B5: Operating, distributions & funding
B6: AFFO / operating cash flow ($m) | C6: ='P&L'!C18 -> 107.6 | D6: ='P&L'!D18 -> 108.9 | E6: ='P&L'!E18 -> 112.87698 | F6: ='P&L'!F18 -> 114.74978 | G6: ='P&L'!G18 -> 118.08533 | H6: ='P&L'!H18 -> 121.81589 | I6: ='P&L'!I18 -> 125.45858
B7: (less) Distributions paid | C7: ='P&L'!C27 -> 109.2624 | D7: ='P&L'!D27 -> 110.3232 | E7: ='P&L'!E27 -> 114.37698 | F7: ='P&L'!F27 -> 116.24978 | G7: ='P&L'!G27 -> 119.58533 | H7: ='P&L'!H27 -> 123.31589 | I7: ='P&L'!I27 -> 126.95858
B8: (less) On-market buy-back | C8: =Assumptions!C37 -> 0 | D8: =Assumptions!D37 -> 20 | E8: =Assumptions!E37 -> 8 | F8: =Assumptions!F37 -> 0 | G8: =Assumptions!G37 -> 0 | H8: =Assumptions!H37 -> 0 | I8: =Assumptions!I37 -> 0
B9: (less) Scheduled debt amortisation | C9: =Debt!C9 -> 0 | D9: =Debt!D9 -> 0 | E9: =Debt!E9 -> 0 | F9: =Debt!F9 -> 0 | G9: =Debt!G9 -> 0 | H9: =Debt!H9 -> 0 | I9: =Debt!I9 -> 0
B10: Net change in cash before revolver ($m) | C10: =C6-C7-C8-C9 -> -1.6624 | D10: =D6-D7-D8-D9 -> -21.4232 | E10: =E6-E7-E8-E9 -> -9.5 | F10: =F6-F7-F8-F9 -> -1.5 | G10: =G6-G7-G8-G9 -> -1.5 | H10: =H6-H7-H8-H9 -> -1.5 | I10: =I6-I7-I8-I9 -> -1.5
B11: Opening cash ($m) | C11: 5 | D11: =C13 -> 3.3376 | E11: =D13 -> 3 | F11: =E13 -> 3 | G11: =F13 -> 3 | H11: =G13 -> 3 | I11: =H13 -> 3
B12: Revolver draw to fund shortfall ($m) | C12: =MAX(0,3-(C11+C10)) -> 0 | D12: =MAX(0,3-(D11+D10)) -> 21.0856 | E12: =MAX(0,3-(E11+E10)) -> 9.5 | F12: =MAX(0,3-(F11+F10)) -> 1.5 | G12: =MAX(0,3-(G11+G10)) -> 1.5 | H12: =MAX(0,3-(H11+H10)) -> 1.5 | I12: =MAX(0,3-(I11+I10)) -> 1.5
B13: Closing cash ($m) | C13: =C11+C10+C12 -> 3.3376 | D13: =D11+D10+D12 -> 3 | E13: =E11+E10+E12 -> 3 | F13: =F11+F10+F12 -> 3 | G13: =G11+G10+G12 -> 3 | H13: =H11+H10+H12 -> 3 | I13: =I11+I10+I12 -> 3
B15: Distribution coverage - cash basis
B16: Operating cash flow (FFO less cash incentives, $m) | C16: ='P&L'!C12-Assumptions!C32 -> 108.6 | D16: ='P&L'!D12-Assumptions!D32 -> 109.9 | E16: ='P&L'!E12-Assumptions!E32 -> 113.87698 | F16: ='P&L'!F12-Assumptions!F32 -> 115.74978 | G16: ='P&L'!G12-Assumptions!G32 -> 119.08533 | H16: ='P&L'!H12-Assumptions!H32 -> 122.81589 | I16: ='P&L'!I12-Assumptions!I32 -> 126.45858
B17: AFFO - after maintenance capex ($m) | C17: ='P&L'!C18 -> 107.6 | D17: ='P&L'!D18 -> 108.9 | E17: ='P&L'!E18 -> 112.87698 | F17: ='P&L'!F18 -> 114.74978 | G17: ='P&L'!G18 -> 118.08533 | H17: ='P&L'!H18 -> 121.81589 | I17: ='P&L'!I18 -> 125.45858
B18: Distributions paid ($m) | C18: ='P&L'!C27 -> 109.2624 | D18: ='P&L'!D27 -> 110.3232 | E18: ='P&L'!E27 -> 114.37698 | F18: ='P&L'!F27 -> 116.24978 | G18: ='P&L'!G27 -> 119.58533 | H18: ='P&L'!H27 -> 123.31589 | I18: ='P&L'!I27 -> 126.95858
B19: Operating cash flow cover (x) | C19: =C16/C18 -> 0.99393753 | D19: =D16/D18 -> 0.996164 | E19: =E16/E18 -> 0.99562849 | F19: =F16/F18 -> 0.99569892 | G19: =G16/G18 -> 0.99581889 | H19: =H16/H18 -> 0.99594537 | I19: =I16/I18 -> 0.99606171
B20: AFFO cover (x) | C20: =C17/C18 -> 0.98478525 | D20: =D17/D18 -> 0.98709972 | E20: =E17/E18 -> 0.98688547 | F20: =F17/F18 -> 0.98709675 | G20: =G17/G18 -> 0.98745666 | H20: =H17/H18 -> 0.98783612 | I20: =I17/I18 -> 0.98818512

Sheet Balance Sheet
B2: Balance Sheet & NTA
C4: FY24A | D4: FY25A | E4: FY26E | F4: FY27E | G4: FY28E | H4: FY29E | I4: FY30E
B5: Assets
B6: Investment properties ($m) | C6: =Assumptions!C42 -> 2730 | D6: =Assumptions!D42 -> 2858 | E6: =Assumptions!E42 -> 2935.5546 | F6: =Assumptions!F42 -> 3000.5109 | G6: =Assumptions!G42 -> 3083.109 | H6: =Assumptions!H42 -> 3166.0754 | I6: =Assumptions!I42 -> 3249.3179
B7: Retained minority interest (divested assets) | C7: 0 | D7: 0 | E7: 0 | F7: 0 | G7: 0 | H7: 0 | I7: 0
B8: Cash ($m) | C8: 5 | D8: 5 | E8: ='Cash Flow'!E13 -> 3 | F8: ='Cash Flow'!F13 -> 3 | G8: ='Cash Flow'!G13 -> 3 | H8: ='Cash Flow'!H13 -> 3 | I8: ='Cash Flow'!I13 -> 3
B9: Other assets ($m) | C9: 5 | D9: 5 | E9: 5 | F9: 5 | G9: 5 | H9: 5 | I9: 5
B10: Total assets ($m) | C10: =SUM(C6:C9) -> 2740 | D10: =SUM(D6:D9) -> 2868 | E10: =SUM(E6:E9) -> 2943.5546 | F10: =SUM(F6:F9) -> 3008.5109 | G10: =SUM(G6:G9) -> 3091.109 | H10: =SUM(H6:H9) -> 3174.0754 | I10: =SUM(I6:I9) -> 3257.3179
B12: Liabilities
B13: Borrowings - net debt ($m) | C13: =Debt!C12 -> 900 | D13: =Debt!D12 -> 935 | E13: =Debt!E12 -> 949.5 | F13: =Debt!F12 -> 956 | G13: =Debt!G12 -> 962.5 | H13: =Debt!H12 -> 969 | I13: =Debt!I12 -> 975.5
B14: Derivatives & other liabilities ($m) | C14: 10 | D14: 10 | E14: 10 | F14: 10 | G14: 10 | H14: 10 | I14: 10
B15: Total liabilities ($m) | C15: =C13+C14 -> 910 | D15: =D13+D14 -> 945 | E15: =E13+E14 -> 959.5 | F15: =F13+F14 -> 966 | G15: =G13+G14 -> 972.5 | H15: =H13+H14 -> 979 | I15: =I13+I14 -> 985.5
B17: Equity
B18: Net assets / equity ($m) | C18: =C10-C15 -> 1830 | D18: =D10-D15 -> 1923 | E18: =E10-E15 -> 1984.0546 | F18: =F10-F15 -> 2042.5109 | G18: =G10-G15 -> 2118.609 | H18: =H10-H15 -> 2195.0754 | I18: =I10-I15 -> 2271.8179
B30: Per-security metrics
B31: Securities on issue (m) | C31: =Assumptions!C39 -> 663 | D31: =Assumptions!D39 -> 663 | E31: =Assumptions!E39 -> 659.8 | F31: =Assumptions!F39 -> 659.8 | G31: =Assumptions!G39 -> 659.8 | H31: =Assumptions!H39 -> 659.8 | I31: =Assumptions!I39 -> 659.8
B32: Net assets ($m) | C32: =C18 -> 1830 | D32: =D18 -> 1923 | E32: =E18 -> 1984.0546 | F32: =F18 -> 2042.5109 | G32: =G18 -> 2118.609 | H32: =H18 -> 2195.0754 | I32: =I18 -> 2271.8179
B33: NTA per security ($) | C33: =C32/C31 -> 2.760181 | D33: =D32/D31 -> 2.9004525 | E33: =E32/E31 -> 3.0070546 | F33: =F32/F31 -> 3.0956516 | G33: =G32/G31 -> 3.2109866 | H33: =H32/H31 -> 3.32688 | I33: =I32/I31 -> 3.4431917
B34: Disclosed NTA (calibration check) | C34: 2.76 | D34: 2.9 | E34: 2.9

Sheet Valuation
B2: Valuation - NAV, cap-rate sensitivity, DDM, FFO multiple
C4: FY24A | D4: FY25A | E4: FY26E | F4: FY27E | G4: FY28E | H4: FY29E | I4: FY30E
B5: 1. NAV / NTA
B6: NTA per security ($) | C6: ='Balance Sheet'!C33 -> 2.760181 | D6: ='Balance Sheet'!D33 -> 2.9004525 | E6: ='Balance Sheet'!E33 -> 3.0070546 | F6: ='Balance Sheet'!F33 -> 3.0956516 | G6: ='Balance Sheet'!G33 -> 3.2109866 | H6: ='Balance Sheet'!H33 -> 3.32688 | I6: ='Balance Sheet'!I33 -> 3.4431917
B7: Premium / (discount) at current price | C7: =Control!$E$5/C6-1 -> -0.094262295 | D7: =Control!$E$5/D6-1 -> -0.13806552 | E7: =Control!$E$5/E6-1 -> -0.16862169 | F7: =Control!$E$5/F6-1 -> -0.19241558 | G7: =Control!$E$5/G6-1 -> -0.22142311 | H7: =Control!$E$5/H6-1 -> -0.24854519 | I7: =Control!$E$5/I6-1 -> -0.27392948
B9: 2. Cap-rate (NAV) sensitivity - FY26E value per security ($)
B10: WACR shift (bps) | D10: -50 | E10: -25 | F10: 0 | G10: 25 | H10: 50
B11: Implied portfolio value ($m) | D11: =Assumptions!E43/(Assumptions!E44+D10/10000) -> 3220.0076 | E11: =Assumptions!E43/(Assumptions!E44+E10/10000) -> 3071.2087 | F11: =Assumptions!E43/(Assumptions!E44+F10/10000) -> 2935.5546 | G11: =Assumptions!E43/(Assumptions!E44+G10/10000) -> 2811.3772 | H11: =Assumptions!E43/(Assumptions!E44+H10/10000) -> 2697.2791
B12: NAV per security ($) | D12: =(D11+'Balance Sheet'!E7+'Balance Sheet'!E8+'Balance Sheet'!E9-Debt!E12-'Balance Sheet'!E14)/'Balance Sheet'!E31 -> 3.4381746 | E12: =(E11+'Balance Sheet'!E7+'Balance Sheet'!E8+'Balance Sheet'!E9-Debt!E12-'Balance Sheet'!E14)/'Balance Sheet'!E31 -> 3.2126534 | F12: =(F11+'Balance Sheet'!E7+'Balance Sheet'!E8+'Balance Sheet'!E9-Debt!E12-'Balance Sheet'!E14)/'Balance Sheet'!E31 -> 3.0070546 | G12: =(G11+'Balance Sheet'!E7+'Balance Sheet'!E8+'Balance Sheet'!E9-Debt!E12-'Balance Sheet'!E14)/'Balance Sheet'!E31 -> 2.81885 | H12: =(H11+'Balance Sheet'!E7+'Balance Sheet'!E8+'Balance Sheet'!E9-Debt!E12-'Balance Sheet'!E14)/'Balance Sheet'!E31 -> 2.6459216
B14: 3. Income yields (at current price)
B15: FY26E distribution yield | E15: ='P&L'!E24/100/Control!E5 -> 0.069340393
B16: FY26E FFO yield | E16: ='P&L'!E20/100/Control!E5 -> 0.069340393
B17: FY26E AFFO yield | E17: ='P&L'!E22/100/Control!E5 -> 0.068431027
B19: 4. Dividend discount (DDM) - PV of distributions FY26E-FY30E + terminal
B20: Required return Ke (%) | E20: 0.095
B21: Terminal growth g (%) | E21: 0.02
B22: DPS per year (cps) | E22: ='P&L'!E24 -> 17.335098 | F22: ='P&L'!F24 -> 17.618943 | G22: ='P&L'!G24 -> 18.124481 | H22: ='P&L'!H24 -> 18.68989 | I22: ='P&L'!I24 -> 19.241979
B23: Discount period (yrs) | E23: 1 | F23: 2 | G23: 3 | H23: 4 | I23: 5
B24: PV of DPS ($/sec) | E24: =E22/100/(1+$E$20)^E23 -> 0.1583114 | F24: =F22/100/(1+$E$20)^F23 -> 0.14694392 | G24: =G22/100/(1+$E$20)^G23 -> 0.13804581 | H24: =H22/100/(1+$E$20)^H23 -> 0.13000207 | I24: =I22/100/(1+$E$20)^I23 -> 0.12223037
B25: Terminal value ($/sec, undiscounted) | I25: =I22/100*(1+$E$21)/($E$20-$E$21) -> 2.6169091
B26: PV of terminal value ($/sec) | I26: =I25/(1+$E$20)^I23 -> 1.6623331
B27: DDM value per security ($) | E27: =SUM(E24:I24)+I26 -> 2.3578666
B29: 5. FFO multiple
B30: Target FFO multiple (x) | E30: 13
B31: FY26E FFO per security (cps) | E31: ='P&L'!E20 -> 17.335098
B32: FFO-multiple value per security ($) | E32: =E30*E31/100 -> 2.2535628
B34: 6. Equity DCF - per-unit EPU (FFO/u) discounted to NPV, market-PE terminal
B35: Risk-free: ACGB 10yr (from Rates & Macro, %) | E35: ='Rates & Macro'!E19 -> 0.043
B36: Equity risk premium (%) | E36: 0.055
B37: Equity beta (x) | E37: 0.75
B38: CAPM cost of equity (%) | E38: =E35+E37*E36 -> 0.08425
B39: Discount rate / required return (%) [OVERRIDE] | E39: 0.12
B41: Terminal FFO multiple (PE) - quant & qual build
B42: Base market / A-REIT sector FFO multiple (x) | E42: 14
B43: (+) Industrial sub-sector premium (x) | E43: 1
B44: (+/-) Quant: gearing & balance-sheet headroom (x) | E44: 0
B45: (+/-) Quant: AFFO cash cover of distribution (x) | E45: -0.25
B46: (+/-) Quant: under-rent / reversion runway (x) | E46: -0.25
B47: (+/-) Qual: management (internal + / external -) (x) | E47: 0.5
B48: (+/-) Qual: portfolio quality & takeover optionality (x) | E48: -0.25
...

Sheet Returns & Simulation
B2: Returns & Simulation - 5yr levered IRR, terminal exit, sensitivities, Monte Carlo
B4: Return inputs
B5: Entry price ($/security) | E5: =Control!E5 -> 2.5
B6: Hold period (years) | E6: 5
B7: Exit capitalisation rate (%) | E7: 0.0575
B8: Exit selling costs (%) | E8: 0.01
B9: Terminal NOI growth into exit (%) | E9: 0.025
B11: Exit value build (end FY30E)
B12: FY30E NOI ($m) | E12: =Assumptions!I43 -> 183.91139
B13: Forward NOI at exit ($m) | E13: =E12*(1+E9) -> 188.50918
B14: Exit portfolio value ($m) | E14: =E13/E7 -> 3278.4205
B15: + retained minority interest ($m) | E15: ='Balance Sheet'!I7 -> 0
B16: + cash ($m) | E16: ='Cash Flow'!I13 -> 3
B17: + other assets ($m) | E17: ='Balance Sheet'!I9 -> 5
B18: - net debt ($m) | E18: =Debt!I12 -> 975.5
B19: - other liabilities ($m) | E19: ='Balance Sheet'!I14 -> 10
B20: Exit equity ($m) | E20: =E14+E15+E16+E17-E18-E19 -> 2300.9205
B21: Securities on issue (m) | E21: =Assumptions!I39 -> 659.8
B22: Exit equity per security ($) | E22: =E20/E21 -> 3.4872999
B23: Exit value per security, net of costs ($) | E23: =E22*(1-E8) -> 3.4524269
B25: 5-year levered cash flow to equity (per security)
C26: t0 (today) | D26: FY26E | E26: FY27E | F26: FY28E | G26: FY29E | H26: FY30E + exit
B27: Distribution received ($/sec) | C27: 0 | D27: ='P&L'!E24/100 -> 0.17335098 | E27: ='P&L'!F24/100 -> 0.17618943 | F27: ='P&L'!G24/100 -> 0.18124481 | G27: ='P&L'!H24/100 -> 0.1868989 | H27: ='P&L'!I24/100 -> 0.19241979
B28: Exit proceeds ($/sec) | H28: =E23 -> 3.4524269
B29: Net cash flow ($/sec) | C29: =-E5 -> -2.5 | D29: =D27 -> 0.17335098 | E29: =E27 -> 0.17618943 | F29: =F27 -> 0.18124481 | G29: =G27 -> 0.1868989 | H29: =H27+H28 -> 3.6448467
B31: 5-year levered equity IRR | E31: =IRR(C29:H29) -> 0.13100608
B32: Equity multiple (MOIC) | E32: =(SUM(D29:G29)+H29)/E5 -> 1.7450123
B33: Total distributions over hold ($/sec) | E33: =SUM(D27:H27) -> 0.91010391
B35: Cap-rate sensitivity - live IRR (exit cap on rows)
B36: Exit cap | C36: t0 | D36: FY26E | E36: FY27E | F36: FY28E | G36: FY29E | H36: FY30E+exit | I36: IRR | J36: MOIC
B37: 0.05 | C37: =-$E$5 -> -2.5 | D37: =$D$27 -> 0.17335098 | E37: =$E$27 -> 0.17618943 | F37: =$F$27 -> 0.18124481 | G37: =$G$27 -> 0.1868989 | H37: =$H$27+(($E$13/$B37)+$E$15+$E$16+$E$17-$E$18-$E$19)/$E$21*(1-$E$8) -> 4.3827149 | I37: =IRR(C37:H37) -> 0.16882488 | J37: =(SUM(D37:G37)+H37)/$E$5 -> 2.0401596
B38: 0.0525 | C38: =-$E$5 -> -2.5 | D38: =$D$27 -> 0.17335098 | E38: =$E$27 -> 0.17618943 | F38: =$F$27 -> 0.18124481 | G38: =$G$27 -> 0.1868989 | H38: =$H$27+(($E$13/$B38)+$E$15+$E$16+$E$17-$E$18-$E$19)/$E$21*(1-$E$8) -> 4.1133345 | I38: =IRR(C38:H38) -> 0.1556184 | J38: =(SUM(D38:G38)+H38)/$E$5 -> 1.9324074
B39: 0.055 | C39: =-$E$5 -> -2.5 | D39: =$D$27 -> 0.17335098 | E39: =$E$27 -> 0.17618943 | F39: =$F$27 -> 0.18124481 | G39: =$G$27 -> 0.1868989 | H39: =$H$27+(($E$13/$B39)+$E$15+$E$16+$E$17-$E$18-$E$19)/$E$21*(1-$E$8) -> 3.8684431 | I39: =IRR(C39:H39) -> 0.14303286 | J39: =(SUM(D39:G39)+H39)/$E$5 -> 1.8344509
B40: 0.0575 | C40: =-$E$5 -> -2.5 | D40: =$D$27 -> 0.17335098 | E40: =$E$27 -> 0.17618943 | F40: =$F$27 -> 0.18124481 | G40: =$G$27 -> 0.1868989 | H40: =$H$27+(($E$13/$B40)+$E$15+$E$16+$E$17-$E$18-$E$19)/$E$21*(1-$E$8) -> 3.6448467 | I40: =IRR(C40:H40) -> 0.13100608 | J40: =(SUM(D40:G40)+H40)/$E$5 -> 1.7450123
B41: 0.06 | C41: =-$E$5 -> -2.5 | D41: =$D$27 -> 0.17335098 | E41: =$E$27 -> 0.17618943 | F41: =$F$27 -> 0.18124481 | G41: =$G$27 -> 0.1868989 | H41: =$H$27+(($E$13/$B41)+$E$15+$E$16+$E$17-$E$18-$E$19)/$E$21*(1-$E$8) -> 3.4398833 | I41: =IRR(C41:H41) -> 0.11948421 | J41: =(SUM(D41:G41)+H41)/$E$5 -> 1.663027
B42: 0.0625 | C42: =-$E$5 -> -2.5 | D42: =$D$27 -> 0.17335098 | E42: =$E$27 -> 0.17618943 | F42: =$F$27 -> 0.18124481 | G42: =$G$27 -> 0.1868989 | H42: =$H$27+(($E$13/$B42)+$E$15+$E$16+$E$17-$E$18-$E$19)/$E$21*(1-$E$8) -> 3.251317 | I42: =IRR(C42:H42) -> 0.10842034 | J42: =(SUM(D42:G42)+H42)/$E$5 -> 1.5876004
B43: 0.065 | C43: =-$E$5 -> -2.5 | D43: =$D$27 -> 0.17335098 | E43: =$E$27 -> 0.17618943 | F43: =$F$27 -> 0.18124481 | G43: =$G$27 -> 0.1868989 | H43: =$H$27+(($E$13/$B43)+$E$15+$E$16+$E$17-$E$18-$E$19)/$E$21*(1-$E$8) -> 3.0772558 | I43: =IRR(C43:H43) -> 0.097773339 | J43: =(SUM(D43:G43)+H43)/$E$5 -> 1.517976
B44: 0.07 | C44: =-$E$5 -> -2.5 | D44: =$D$27 -> 0.17335098 | E44: =$E$27 -> 0.17618943 | F44: =$F$27 -> 0.18124481 | G44: =$G$27 -> 0.1868989 | H44: =$H$27+(($E$13/$B44)+$E$15+$E$16+$E$17-$E$18-$E$19)/$E$21*(1-$E$8) -> 2.7664322 | I44: =IRR(C44:H44) -> 0.077589024 | J44: =(SUM(D44:G44)+H44)/$E$5 -> 1.3936465
B46: Two-way: exit cap (rows) x terminal NOI shift (cols) -> equity MOIC
B47: cap \ NOI | C47: -0.1 | D47: -0.05 | E47: 0 | F47: 0.05 | G47: 0.1
...
